Workbook

Sheet 50-state matrix
A1: State | B1: Letter grade: did the restrictions keep property taxes down? (points, deductions, reasons) | C1: Four-regime scorecard (spending · levy · assessment · rate) | D1: Local spending limit (budgets, appropriations or general revenue) | E1: Local property tax levy limit (cap on property tax revenue growth) | F1: Property tax assessment caps (with all exclusions) | G1: Property tax rate limits (specific rates) | H1: School districts covered by the limits? (education exclusions) | I1: A statewide property tax (additional tax or local pass-through?) | J1: Homestead Exemption (property tax) | K1: Property tax credits, circuit breakers & rebates (separate from homestead exemptions) | L1: State subsidies to local governments to reduce property taxes (mechanism) | M1: Truth-in-taxation laws | N1: Property tax rollback protections | O1: Supermajority requirement for local tax increases (thresholds) | P1: November-ballot requirement for local spending/tax increases | Q1: Statewide restrictions on how localities may spend property tax dollars | R1: Jurisdictions with property taxing authority | S1: Has it worked? Short verdict, then loopholes, workarounds and the full record (incl. shifts to sales/income taxes or fees) | T1: Conservative & free-market analyses (State Policy Network groups, taxpayer groups): links with synopses | U1: Recent reform efforts (2020–2026) & outcomes | V1: Tax Foundation 2026 ranking: effective property tax rate on owner-occupied homes (1 = lowest), with the 2010 rate by the same measure | W1: Notes | X1: Source URLs
A2: Alabama | B2: D. Restriction points 4.5 of 18 (assessment cap 1; rate cap 2; school districts covered 1; use restrictions 0.5). Deductions: built-in loopholes -1; workarounds in practice -0.5; state buydowns +0; data record +0. Total 3 = D (A 11+, B 8.5-10.9, C 5.5-8.4, D 3-5.4, F under 3). Why: Built-in loopholes -1: the 7% assessment cap sunsets after 2027 and excludes new construction, ownership changes and TIF-district property; Mountain Brook, Vestavia Hills and Huntsville are exempt from the Lid Bill ceiling. Workarounds -0.5: local governments lean on sales taxes, fees and occupational taxes (fees 52.5% of local own-source revenue), though voters still reject millage increases (Tuscaloosa, 2024). Buydowns 0: no state program buys down local rates. Record 0: the lowest burden in the country (1.49% of personal income; 0.38% effective rate) offsets some of the fastest recent growth (real per-person collections up 12.9% FY2019-FY2024; U.S. -1.1%). | C2: =((LEFT(D2,3)="Yes")+(LEFT(E2,3)="Yes")+(LEFT(F2,3)="Yes")+(LEFT(G2,3)="Yes"))&" of 4 in force"&IF(((LEFT(D2,7)="Partial")+(LEFT(E2,7)="Partial")+(LEFT(F2,7)="Partial")+(LEFT(G2,7)="Partial"))>0," + "&((LEFT(D2,7)="Partial")+(LEFT(E2,7)="Partial")+(LEFT(F2,7)="Partial")+(LEFT(G2,7)="Partial"))&" partial","")&CHAR(10)&CHAR(10)&IF(LEFT(D2,3)="Yes","✓",IF(LEFT(D2,7)="Partial","◐","✗"))&" Spending limit"&CHAR(10)&IF(LEFT(E2,3)="Yes","✓",IF(LEFT(E2,7)="Partial","◐","✗"))&" Levy limit"&CHAR(10)&IF(LEFT(F2,3)="Yes","✓",IF(LEFT(F2,7)="Partial","◐","✗"))&" Assessment cap"&CHAR(10)&IF(LEFT(G2,3)="Yes","✓",IF(LEFT(G2,7)="Partial","◐","✗"))&" Rate cap" | D2: No. Alabama puts no growth cap on county, municipal or school budgets; local units must simply adopt balanced budgets. The state budget rules cited in earlier versions of this matrix (limits tied to projected revenue) govern state appropriations only. | E2: No. No cap on growth in total property tax revenue. Two features restrain it indirectly: no millage can rise above constitutional limits without a public hearing, an act of the Legislature and a local referendum, and the temporary 7% assessment cap (tax years 2025-2027) slows valuation growth on most parcels. New construction, newly discovered property and growth inside TIF districts still add revenue with no vote. | F2: Partial. Statewide but temporary. Act 2024-344 caps the annual increase in assessed value of Class II real property (commercial, rental and other property not otherwise classed) and Class III real property (owner-occupied homes, farms, forest land, historic property) at 7% a year, starting with the 2025 tax year. Market and current-use values are still determined each year; the cap applies to assessed value only. Class I utility property is not covered. Exclusions (value may rise more than 7%): never-assessed property; additions or improvements (ordinary maintenance does not count); a change in classification; a change in ownership, except transfers between spouses or family members for no or nominal consideration (including at death) and redemptions after foreclosure or tax sale; property inside a tax increment financing district. Sunset: the cap runs through the fiscal year beginning Oct. 1, 2027 unless extended. Authority: Code of Ala. §40-7-2.2 (Act 2024-344, HB 73, signed May 2024). | G2: Yes. Two layers. 1) Overall cap ("Lid Bill"): total ad valorem tax from all levies on a property may not exceed 1% of fair market value for Class III (owner-occupied homes, farm and timber land), 1.25% for Class IV (personal vehicles), 1.5% for Class II and 2% for Class I utility property. Mountain Brook, Vestavia Hills and Huntsville are exempt from this ceiling. 2) Millage caps by levy: state 6.5 mills; county general 5 mills; municipal 5 mills; every school district must levy at least 10 mills (a floor). Assessment ratios are fixed at 10% (Class III), 15% (IV), 20% (II) and 30% (I). Any millage above constitutional limits requires a proposal by the governing body after a public hearing, an act of the Legislature, and majority approval of local voters at a special election. Combined millage in most places sits well below the 100-mill equivalent of the 1% Class III ceiling, so the act-plus-referendum requirement is the working check. Authority: Ala. Const. §217 (Amendment 373, "Lid Bill," ratified Nov. 1978); §§214-216; §269.08 (Amendment 778, 2006, 10-mill school minimum). | H2: Yes. School millage is bound by the same constitutional caps, the act-plus-referendum rule and the 7% assessment cap. The Constitution also sets a 10-mill minimum school levy in every district, and the state Foundation Program counts 10 mills as the required local share, so school taxes have a floor as well as a ceiling. | I2: Yes. An additional state tax that does not replace local levies: 6.5 mills on all taxable property, collected by county officials and remitted to the state. 3 mills go to education (§260), 2.5 mills to the State General Fund, and 1 mill to old-age assistance (DHR share capped at $20.77 million) with the remainder to the Alabama Veterans' Assistance Fund. Homeowners 65+, and disabled or blind homeowners, are exempt from the state levy on their homestead. FY2022 state property tax revenue: about $496 million (Census). | J2: Yes. Regular homestead: $4,000 of assessed value exempt from state taxes and $2,000 of assessed value exempt from county taxes (about $40,000 and $20,000 of market value at the 10% ratio). Counties, cities and other taxing units may raise their exemption to $4,000 of assessed value. Age 65+: exempt from all state taxes; with state AGI under $12,000, $5,000 of assessed value exempt from county taxes; with combined federal taxable income of $12,000 or less, exempt from all ad valorem taxes. Permanently and totally disabled: exempt from all ad valorem taxes, no income test. Blind: exempt from state taxes plus $5,000 assessed value from county taxes. Maximum 160 acres. Many counties add their own senior exemptions through local constitutional amendments (e.g., Limestone County, HB 310 of 2026). Authority: Code of Ala. §§40-9-19 to 40-9-21. | K2: No. No circuit breaker, renter credit or state-funded property tax rebate. Relief comes through exemptions and the low 10% residential assessment ratio. | L2: No. No state program reimburses local governments for property tax revenue lost to state law or pays them to lower rates. The 2025 increase in the business personal property exemption to $100,000 (HB 543) applies to the state levy; counties and cities may adopt a matching local exemption with no state reimbursement. The Foundation Program, which counts 10 mills of local tax toward each district's share, is general school aid and does not count. Authority: Ala. Code § 40-9-1; HB 543 (2025 Reg. Sess.); Ala. Admin. Code r. 810-4-1-.14; Ala. Code § 16-13-231. | M2: No. | N2: No. No rollback, revenue-neutral or certified rate after reappraisal. Rising values raise revenue automatically, limited only by the temporary 7% assessment cap. | O2: No. Millage above constitutional limits needs a simple majority of local voters (after a public hearing and a legislative act). No supermajority of voters or of a governing body is required. | P2: No. Millage referenda are held at special elections; there is no requirement to hold them at November general elections. | Q2: Yes. Alabama millage is purpose-specific by design. Each levy exists under a constitutional section or local amendment that names its purpose: county general (5 mills), county road and bridge, county and district school taxes (with the 10-mill school minimum), and special levies for fire, library, hospital, health and similar services authorized county by county. Dedicated levies may fund only their stated purpose. The state's 6.5 mills are also earmarked (education, General Fund, old-age assistance/veterans). | R2: State (6.5 mills); 67 counties; 462 municipalities; county and city school systems (138 independent school districts in the Census count), whose taxes are levied countywide or by school tax district; special districts created by local act or constitutional amendment (fire protection, hospital, library and similar). Census of Governments 2022: 1,208 local governments, including 541 special districts; most of those special districts are housing, water and soil-conservation authorities that levy no property tax. | S2: Verdict: Failed. Property tax per person rose 48.0% after inflation from FY2002 to FY2024, against 25.9% for the U.S., and grew 12.9% from FY2019 to FY2024 while the U.S. figure fell 1.1%. Why it leaks: The 1978 Lid Bill (Amendment 373) caps millage, yet Alabama has no levy limit or rollback, so local governments collect more each year at the same millage with no vote. No law caps local budgets. Alabama also lacks truth in taxation, which offers transparency and accountability, so these increases reach bills with no notice or hearing. The 7% assessment cap in Act 2024-344 runs only through 2027 unless extended and excludes improvements and property inside TIF districts. How localities get around it: Local constitutional amendments add millage one county at a time. Huntsville is one of three cities exempt from the Lid Bill ceiling. Full record: Has it worked? On the size of the tax, yes. On growth, no. The record (Census, BEA, ACS): state and local property tax was $849 per person in FY2024 (U.S. $2,132), 1.49% of personal income (49th-highest of 50; U.S. 2.89%). After inflation, collections per person (all state and local property tax divided by residents) rose 48.0% from FY2002 to FY2024 (U.S. +25.9%) and rose 12.9% from FY2019 to FY2024 (U.S. -1.1%). The median homeowner paid $890 in 2024 (U.S. $3,211); the median bill rose 20.8% after inflation from 2010 to 2024 (U.S. +9.3%). The Tax Foundation's 2026 ranking puts its effective property tax rate on owner-occupied homes at 0.37%, 2nd-lowest of 50. By the same measure it was 0.37% in 2010 (U.S. 1.00% in 2010, 0.94% in 2024). Why: the 1978 Lid Bill froze low assessment ratios, capped total bills and requires a legislative act plus a referendum for every millage increase, which keeps the level low; with no levy limit and no rollback, rising values flow straight into revenue. The temporary 7% assessment cap began with the 2025 tax year. Revenue shift: local governments moved to other taxes. Property tax supplies only 40% of local tax revenue in Alabama versus 70% nationally, and sales taxes supply 48% (Census, FY2022). Fees and charges are 52.5% of local own-source revenue (34% nationally). The average combined sales tax rate is 9.46%, 5th-highest in the U.S., with local rates up to 11%, and groceries remain taxable. Birmingham and other localities also levy occupational license taxes on wages. Workarounds: local constitutional amendments add millage or exemptions one county at a time; three cities are exempt from the Lid Bill ceiling; TIF-district property is excluded from the 7% cap; current-use valuation keeps timber and farmland taxes very low. Special elections: millage referenda go to special elections with low turnout. In Tuscaloosa the school board, city council and Legislature all approved an 11.5-mill increase (22%, about $17.25 million a year for city schools), and voters still rejected it on Sept. 24, 2024, 5,704 to 4,999, with 16.5% turnout (Alabama Political Reporter). The vote requirement binds even where every elected body backs an increase. Big cities: Tuscaloosa's city rate was already 51.5 mills before that vote, against a 42-mill statewide average (Alabama Political Reporter); larger cities such as Birmingham add occupational taxes on wages (see Revenue shift). Pushback: the Association of County Commissions wants the 7% cap to expire in 2027, citing lost revenue (Randolph County: $1.8 million over two years). The Alabama Policy Institute wants it made permanent (2026 report). | T2: - 1819 News (launched by the Alabama Policy Institute), "Alabama's 7% property tax reappraisal cap expires in 2027 — Will lawmakers extend it?" (Aug. 22, 2026). Reports Sen. David Sessions's plan to extend the cap in 2027, lists every exclusion in the law and gives the county commissions' case for letting it lapse. https://1819news.com/news/item/alabamas-7-property-tax-reappraisal-cap-expires-in-2027-will-lawmakers-extend-it - Alabama Policy Institute, "Alabama Policy Institute Launches Landmark Alabama Tax Relief Report: A Multi-Phase Roadmap for Economic Growth and Fiscal Discipline" (July 15, 2026). A phased tax-cut plan for the 2027 session paid for by spending restraint. On property tax it calls for making the assessment protections permanent by removing the 2027 sunset, and it warns that cutting income taxes without a population-plus-inflation spending cap would push the burden onto sales and property taxes. https://alabamapolicy.org/2026/07/15/alabama-policy-institute-launches-landmark-alabama-tax-relief-report-a-multi-phase-roadmap-for-economic-growth-and-fiscal-discipline/ - Tax Foundation, "Alabama's 2025 Legislative Session Advances Pro-Growth Tax Reforms" (July 9, 2025). Act 2025-344 raises the business tangible personal property tax exemption from $40,000 to $100,000 in market value, effective October 1, 2025, and ends filing for businesses under the threshold; local jurisdictions may opt in. Similar thresholds elsewhere cost "often less than 1 percent of property tax collections." https://taxfoundation.org/blog/alabama-tax-reform-relief-2025/ - 1819 News (launched by the Alabama Policy Institute), "Ainsworth on new property tax cap: ‘We don’t want anybody to get gouged’" (Aug. 14, 2024). Lt. Gov. Will Ainsworth says calls from owners facing reappraisal increases of 20%, 30% and 40% led to the 7% cap in HB 73 (Rep. Phillip Pettus and Sen. David Sessions), effective October 1, 2024. https://1819news.com/news/item/ainsworth-on-new-property-tax-cap-we-dont-want-anybody-to-get-gouged - Alabama Policy Institute, "API: Top 10 Things the AL Legislature Should Accomplish in 2024" (Feb. 5, 2024). Item 8, "Cap Property Tax," notes that county and municipal rates vary widely, so rising valuations hit some owners far harder than others, and urges an assessment cap "to make property tax increases more predictable and lessen the tax burden of Alabama's homeowners." The Legislature enacted the 7% cap (Act 2024-344) that spring. https://alabamapolicy.org/2024/02/05/api-top-10-things-the-al-legislature-should-accomplish-in-2024/ - Free the People (State Policy Network associate): no Alabama property tax work since 2021 was found. - National School Choice Awareness Foundation (State Policy Network associate): no property tax work since 2021 was found. - Americans for Prosperity-Alabama: no property tax item since 2021 was found. Linked list: 5 items on the Analyses sheet (filter State = Alabama); every source URL is linked on the Sources sheet. | U2: 2024: HB 73 (Act 2024-344) passed after large reappraisal increases, creating the 7% annual assessment cap for tax years 2025-2027 (Senate sponsor David Sessions sought 5%). 2026 session: no statewide property tax change. HB 167 (Rep. Kiel) would have replaced the 7% cap with the CPI-U increase; it was referred to House Ways and Means General Fund on Jan. 13, 2026, had not moved by the Alabama State Bar's March 20 tracker and was not enacted. Counties kept adding senior exemptions by local amendment (e.g., Limestone County, HB 310; Colbert and Franklin counties, Acts 2026-28 and 2026-29). 2027 session: extension or tightening of the cap expected to be debated; county commissions oppose extension. Nov. 3, 2026 ballot: four statewide amendments (Lieutenant Governor vacancy and legislative pay, SB 271; merging county school systems, HB 380; school Pledge of Allegiance and student prayer, HB 511; weekly national anthem in schools, SB 5). None concerns property tax (Fox10, Sept. 14, 2026). | V2: 2nd (0.37% effective rate; 0.37% in 2010) | W2: Alabama relies on rate caps: overall 1%/1.25%/1.5%/2% lids, fixed low assessment ratios and a legislative-act-plus-referendum requirement for any millage increase, plus a 7% assessment cap through 2027. It has no spending cap, levy cap or truth-in-taxation law. Property taxes are among the nation's lowest; local governments make up the difference with sales taxes, occupational taxes and fees. | X2: https://www.revenue.alabama.gov/wp-content/uploads/2025/03/HB73.pdf https://www.revenue.alabama.gov/property-tax/homestead-exemptions/ https://law.justia.com/constitution/alabama/CA-888542.html https://www.lincolninst.edu/app/uploads/legacy-files/gwipp/upload/sources/Alabama/2021/al_ad_valorem_tax_guide.pdf https://1819news.com/news/item/alabamas-7-property-tax-reappraisal-cap-expires-in-2027-will-lawmakers-extend-it https://legiscan.com/AL/text/HB310/2026 https://apps.lincolninst.edu/uploads/summary-tables/rate-limits-summary-tables/rate-limits-2022-4.xlsx https://www2.census.gov/programs-surveys/gov-finances/tables/2022/22slsstab1.xlsx https://taxfoundation.org/data/all/state/sales-tax-rates/ https://www.revenue.alabama.gov/property-tax/7-cap-information-hb73-act-2024-344/ https://alison.legislature.state.al.us/files/pdf/SearchableInstruments/2026RS/HB167-int.pdf https://www.alabar.org/assets/2026/03/Tax-3.20.26.pdf https://www.fox10tv.com/2026/09/14/decision-2026-alabama-sample-ballots-now-available-nov-3-election/ https://www.alreporter.com/2024/09/25/tuscaloosa-residents-reject-property-tax-increase-for-schools/ https://alabamapolicy.org/2024/02/05/api-top-10-things-the-al-legislature-should-accomplish-in-2024/ https://www.tuscco.com/wp-content/uploads/2026/05/Insert-for-2026-Valuation-Notices-CAP-Doc-3-1.pdf
A3: Alaska | B3: C. Restriction points 6.75 of 18 (spending limit 2; levy limit 2; rate cap 2; school districts covered 0.5; use restrictions 0.25). Deductions: built-in loopholes -1; workarounds in practice -0.5; state buydowns +0; data record +0.5. Total 5.75 = C (A 11+, B 8.5-10.9, C 5.5-8.4, D 3-5.4, F under 3). Why: Built-in loopholes -1: debt taxes sit outside every state limit, the 30-mill cap sits far above most local rates, and the per-capita levy ceiling binds mainly on the North Slope Borough. Workarounds -0.5: the Anchorage Assembly loosened its tax cap in 2015 (voters reversed it in 2016) and drafted a sales tax partly outside the cap; Mat-Su swapped its revenue cap for a 10.5-mill rate cap in 2018. Buydowns 0. Record +0.5: real per-person collections fell 9.6% FY2019-FY2024 and real homeowner bills fell 7.3% 2010-2024, though the burden is above average (3.20% of personal income; 1.06% effective rate). | C3: =((LEFT(D3,3)="Yes")+(LEFT(E3,3)="Yes")+(LEFT(F3,3)="Yes")+(LEFT(G3,3)="Yes"))&" of 4 in force"&IF(((LEFT(D3,7)="Partial")+(LEFT(E3,7)="Partial")+(LEFT(F3,7)="Partial")+(LEFT(G3,7)="Partial"))>0," + "&((LEFT(D3,7)="Partial")+(LEFT(E3,7)="Partial")+(LEFT(F3,7)="Partial")+(LEFT(G3,7)="Partial"))&" partial","")&CHAR(10)&CHAR(10)&IF(LEFT(D3,3)="Yes","✓",IF(LEFT(D3,7)="Partial","◐","✗"))&" Spending limit"&CHAR(10)&IF(LEFT(E3,3)="Yes","✓",IF(LEFT(E3,7)="Partial","◐","✗"))&" Levy limit"&CHAR(10)&IF(LEFT(F3,3)="Yes","✓",IF(LEFT(F3,7)="Partial","◐","✗"))&" Assessment cap"&CHAR(10)&IF(LEFT(G3,3)="Yes","✓",IF(LEFT(G3,7)="Partial","◐","✗"))&" Rate cap" | D3: Partial. No statewide spending or revenue cap on municipalities. The binding limits are local and voter-imposed: Anchorage's 1983 charter "tax cap" sets the maximum total taxes the Municipality may collect each year at the prior year's taxes adjusted for the five-year average change in population and inflation, and the Assembly may not adopt a budget that exceeds it. Other municipalities have adopted their own caps, some since loosened (see Loopholes). Authority: Anchorage Municipal Charter §14.03; Anchorage Municipal Code 12.25. | E3: Partial. State law: a per-capita levy ceiling (AS 29.45.090) limits operating property tax revenue to what a capped rate would raise on a hypothetical tax base of 375%, 300% or 225% of the statewide average per-capita full value (sliding by mill rate), with a flat $1,500-per-resident alternative. It only binds municipalities with exceptionally large tax bases per resident, chiefly the North Slope Borough's oil infrastructure. Local voter-approved caps (Anchorage, Matanuska-Susitna Borough, City of Fairbanks and others) do the work elsewhere. Taxes for voter-approved bonds are excluded from all state limits (AS 29.45.100). Authority: AS 29.45.090, 29.45.100 (enacted 1972). | F3: No. No annual assessment growth cap. Property is assessed at full and true value each year. The mandatory senior/disabled-veteran exemption (first $150,000) is the only statewide shield for long-time owners. | G3: Yes. Operating levies of any municipality may not exceed 30 mills (3% of assessed value) in a year; second-class cities are limited to 20 mills (2%). Taxes for bonded debt are outside the limits. Few municipalities approach 30 mills; most levy well below it. Authority: AS 29.45.090; AS 29.45.590 (second-class cities); AS 29.45.100 (debt excluded). | H3: Partial. Alaska has no independent school districts; boroughs and home-rule/first-class cities fund their schools inside the same 30-mill operating limit. The state foundation formula (AS 14.17.410) requires a minimum local contribution (the equivalent of 2.65 mills on full value) and caps how much more a municipality may contribute, so school-related local taxes have both a floor and a ceiling set by the state. | I3: Partial. The only state property tax is a 20-mill (2%) tax on oil and gas exploration, production and pipeline transportation property. Municipal taxes on the same property are credited against it, so in organized areas it mostly serves as a state backstop; in the unorganized borough the state keeps the full tax. It applies to one industry and does not replace local levies. FY2022 state property tax revenue: about $125 million (Census). Authority: AS 43.56. | J3: Yes. Mandatory: the first $150,000 of assessed value of a permanent home owned and occupied by a resident 65 or older, a veteran with a 50%+ service-connected disability, or certain surviving spouses is exempt from municipal property tax (municipalities may grant more). Local option: municipalities may exempt up to $75,000 of assessed value of any owner-occupied residence (a general "homestead" exemption); whether and how much varies by municipality. There is no statewide general homestead exemption for all owners. Authority: AS 29.45.030(e); AS 29.45.050. | K3: No. No statewide circuit breaker, renter credit or property tax rebate. Some municipalities run local senior hardship programs. The Permanent Fund Dividend is a cash payment unrelated to property tax. | L3: No. State law requires the state to reimburse boroughs and cities for real property tax lost to the mandatory exemption of the first $150,000 of assessed value on homes of residents 65 and older and disabled veterans, prorated when appropriations fall short. The Legislature has not funded the reimbursement since 1997, so no state money reaches municipalities for it; they absorb the cost, which the Alaska Municipal League put at over $105 million a year in 2023. K-12 foundation aid, with its required local contribution, and Community Assistance revenue sharing are general aid and do not count. Authority: AS 29.45.030(e); AS 29.45.030(g); AS 14.17.410; AS 29.60.850. | M3: No. | N3: No. No state rollback rule. In Anchorage the charter tax cap has a similar effect: when assessments rise faster than the cap allows, the mill rate must fall. | O3: No. State law requires no supermajority to raise property taxes. Bonds require majority voter approval. Exceeding local charter caps follows each charter's terms (typically a public vote). | P3: No. Municipal elections are generally held in October (April in Anchorage); bond and tax questions go on those ballots or special elections. | Q3: Partial. Operating levies are general purpose. Borough and city "service area" levies (roads, fire, street lights and similar) may fund only the service in that area, and debt levies are dedicated to the bonds voters approved. | R3: Only municipalities levy property tax: organized boroughs, unified home-rule municipalities and cities. Per Alaska Taxable 2025, 15 of 19 organized boroughs/unified municipalities and 21 of 145 cities levy one. School systems are departments of boroughs and cities (55 dependent school systems in the Census count), and borough service areas levy within the borough's taxing power. The unorganized borough has no local property tax; the state's 20-mill oil and gas property tax applies statewide. Census of Governments 2022: 181 local governments (15 county-type boroughs, 149 municipalities, 17 special districts, none of which levy property tax). | S3: Verdict: Partly. Property tax per person rose 9.0% after inflation from FY2002 to FY2024, against 25.9% for the U.S., and fell 9.6% from FY2019 to FY2024. Why it leaks: The 30-mill operating cap (AS 29.45.090) is a rate cap few municipalities approach, and the per-capita levy ceiling binds chiefly the North Slope Borough. Taxes for voter-approved bonds fall outside all state limits. Alaska has no assessment cap. Restraint comes from local voter caps such as Anchorage's 1983 charter tax cap, and part of the recent decline came from falling oil and gas property tax. How localities get around it: In 2015 the Anchorage Assembly loosened its tax cap formula until voters reversed it with Proposition 8 in 2016. In 2018 the Matanuska-Susitna Borough Assembly replaced its revenue-growth cap with a fixed 10.5-mill rate cap. Full record: Has it worked? Growth has been held down; the level remains high. Statewide limits are loose (a 30-mill cap few municipalities approach and a per-capita ceiling aimed at the North Slope Borough's oil base), so restraint comes from local voter caps, which local officials have tried to loosen. The record (Census, BEA, ACS): state and local property tax was $2,456 per person in FY2024 (U.S. $2,132), 3.20% of personal income (13th-highest of 50; U.S. 2.89%). After inflation, collections per person (all state and local property tax divided by residents) rose 9.0% from FY2002 to FY2024 (U.S. +25.9%) and fell 9.6% from FY2019 to FY2024 (U.S. -1.1%). The median homeowner paid $3,976 in 2024 (U.S. $3,211); the median bill fell 7.3% after inflation from 2010 to 2024 (U.S. +9.3%). The Tax Foundation's 2026 ranking puts its effective property tax rate on owner-occupied homes at 0.94%, 31st-lowest of 50. By the same measure it was 1.00% in 2010 (U.S. 1.00% in 2010, 0.94% in 2024). Why: two forces outside the limits explain part of the decline. The state's oil and gas property tax fell from $215 million to $131 million over the period, and population grew less than 1%. The data cannot separate the effect of local caps such as Anchorage's from those forces. Anchorage: in Oct. 2015 the Assembly loosened the tax cap's growth formula; voters reversed it in April 2016 with Proposition 8 (60%+), which also tied the cap to taxes collected (the looser formula had used the maximum allowable). Anchorage says property taxes have held steady since 1983 under the cap. In 2025 the Assembly drafted a sales tax structured partly "outside the tax cap" before postponing it indefinitely; Mayor LaFrance's 3% sales tax proposal (1% earmarked for property tax relief) was postponed indefinitely in January 2026 in exchange for a one-time $12 million school levy. In April 2026 voters rejected that levy, a $79 million school bond and a police facilities bond while approving seven of ten areawide measures; residents cited rising assessments and an appraisal method change (Anchorage Daily News). Fairbanks: in June 2026 the City of Fairbanks council voted 5-1 to raise its rate from 5.833 to 6.381 mills, partly to pay a 2025 wrongful-conviction settlement, with a further payment due in 2027; the mayor said the usual formula would have produced 7.2 mills (Alaska's News Source, June 13, 2026). The Fairbanks North Star Borough held its FY2027 mill rate flat by drawing about $600,000 from its general fund (Alaska's News Source, May 31, 2026). Matanuska-Susitna Borough: in 2018 the Assembly replaced its revenue-growth cap with a fixed 10.5-mill rate cap, which lets revenue rise with assessed values. Revenue mix: property tax supplies 76% of local taxes (U.S.: 70%); local sales taxes (average 1.82%, up to 7.85%), bed taxes and fees fill the rest. Large resource projects often pay boroughs negotiated payments in lieu of taxes, which take the place of standard levies. | T3: - Alaska Policy Forum, "Testimony: Oppose New Property Taxes" (June 8, 2023; testimony dated April 18, 2023). CEO Bethany Marcum opposed SB 77, which would let boroughs and cities tax "blighted" property, because the bill set no guardrails on what counts as blight and protected only an owner's primary residence; she cited a New Orleans blight-tax effort that collected only 3% of the fines levied. https://alaskapolicyforum.org/2023/06/testimony-tax-blighted-property/ - Alaska Policy Forum and Tax Foundation, Jared Walczak, "Economic Implications of an Alaska Income Tax or Its Alternatives" (Oct. 4, 2022). A full report opposing a state income tax; it finds Alaska would need income tax burdens three times California's to match the average state's reliance on the tax, and it points to New Jersey, where an income tax adopted to cut school reliance on local property taxes "did not translate into lower property tax burdens" (effective rate 2.21% on owner-occupied housing against a 1.08% national average). https://alaskapolicyforum.org/2022/10/economic-implications-of-an-alaska-income-tax-or-its-alternatives/ - Alaska Policy Forum, "Alaska Property Taxes, Ranked" (Aug. 3, 2022). Summarizes the Tax Foundation's ranking (Alaska 24th on property tax burden) and argues that heavy reliance on property tax beats a state income or sales tax: property tax is more transparent, funds local services residents can see, and is already restrained by Alaska's rate and levy limits; urges residents to scrutinize school bonds and levies. https://alaskapolicyforum.org/2022/08/alaska-property-taxes-ranked/ - Americans for Prosperity-Alaska: no Alaska property tax item since 2021 was found. Linked list: 3 items on the Analyses sheet (filter State = Alaska); every source URL is linked on the Sources sheet. | U3: 2026: Governor Dunleavy sought to nearly eliminate state and municipal property taxes on the proposed Alaska LNG pipeline (HB 381 / SB 2001), replacing them with payments tied to gas throughput. The Senate passed a version narrowly in July; the House rejected it; a third special session ended Aug. 25, 2026 without action. 2026 (Anchorage): the mayor's sales tax proposal was tabled in January; in April voters rejected the school bond, the police bond and a one-time levy. 2025: Anchorage Assembly shelved a proposed sales tax (partly for property tax relief) in March. 2016: Anchorage voters tightened the tax cap (Prop 8). 2018: Mat-Su converted its cap to a 10.5-mill rate cap. 2025-2026 (34th Legislature): HB 169 (Rep. Tomaszewski, April 2, 2025) would have raised the mandatory senior and disabled-veteran exemption from $150,000 to $250,000 of assessed value; it never left House Community and Regional Affairs. SB 259 (Sen. Bjorkman, 2026) would have allowed an optional municipal limit on annual increases in the value of owner-occupied homes; it was referred to Senate Finance on April 28, 2026 and was not enacted. In Feb. 2025 Anchorage Assembly Member Sulte drafted a resolution urging the Legislature to authorize a cap modeled on Florida's "Save Our Homes." 2024: late in the session the Senate Finance Committee proposed tripling the senior exemption to $450,000; it did not become law (the 2025 HB 169 text still shows $150,000). Nov. 3, 2026 ballot: Ballot Measure 2 (repeal top-four ranked-choice voting) and Ballot Measure 3 (citizenship requirement for voting); Ballot Measure 1 (campaign contribution limits) was on the Aug. 18 primary ballot. None concerns property tax. | V3: 31st (0.94% effective rate; 1.00% in 2010) | W3: Alaska has a statutory rate cap (30 mills) and a per-capita levy ceiling, but no assessment cap, no truth-in-taxation and no statewide spending limit. Only 36 municipalities levy property tax at all. Restraint, where it exists, comes from voter-adopted municipal caps such as Anchorage's 1983 tax cap, which voters had to defend against Assembly loosening in 2016. | X3: https://www.commerce.alaska.gov/dcra/admin/Taxable/ViewFile/2de31798-e2aa-42c9-8a50-43e1c7c6ddb8 https://www.akleg.gov/basis/statutes.asp#29.45.090 https://www.akleg.gov/basis/statutes.asp#43.56 https://www.muni.org/Departments/Assembly/SiteAssets/Pages/FOCUS-Budget-and-Taxes/2026%20Property%20Taxes%20Fact%20Sheet.pdf https://muni.org/Departments/Assembly/Documents/AIM%208-2025.pdf https://www.adn.com/article/20160405/anchorage-voters-support-tax-cap-initiative-and-marijuana-taxes https://matsugov.us/news/whistle-stop-mat-su-on-the-new-tax-cap https://www.adn.com/politics/alaska-legislature/2026/08/25/3rd-special-session-on-alaska-lng-ending-after-lawmakers-decline-to-take-up-dunleavys-bill/ https://www.alaskasnewssource.com/2025/03/19/anchorage-sales-tax-proposal-go-before-voters-tuesday-night https://www.lincolninst.edu/app/uploads/2025/01/levy_limits_2022.xlsx https://law.justia.com/codes/alaska/title-29/chapter-45/article-1/section-29-45-090/ https://www.adn.com/alaska-news/anchorage/2026/01/14/lafrance-says-anchorage-sales-tax-conversations-will-continue-despite-tabling/ https://www.adn.com/alaska-news/anchorage/2026/05/12/tax-concerns-and-school-district-distrust-shaped-anchorages-mixed-municipal-election-results/ https://www.alaskasnewssource.com/2026/01/10/we-do-math-sales-tax-vs-property-taxes-which-saves-you-more-money/ https://www.akleg.gov/basis/Bill/Detail/34?Root=HB%20169 https://www.akleg.gov/pdf/34/Bills/HB0169A.pdf https://www.akleg.gov/basis/Bill/Detail/34?Root=SB%20259 https://thealaskacurrent.com/2024/05/13/property-tax-cut/ https://muni.org/Departments/Assembly/Documents/DRAFT%20AR%20re%20Property%20Tax%20Excalation%20Limitations.pdf https://www.alaskasnewssource.com/2026/06/13/city-fairbanks-establishes-tax-rate-current-year/ https://www.alaskasnewssource.com/2026/05/31/fairbanks-borough-assembly-passes-fy27-budget-with-no-increase-mill-rate/ https://alaskapolicyforum.org/2023/06/testimony-tax-blighted-property/ https://theballotbrief.com/measures/alaska
